nohup: ignoring input
/home/zfgao/anaconda3/envs/dc/lib/python3.7/site-packages/torch/nn/parallel/data_parallel.py:26: UserWarning: 
    There is an imbalance between your GPUs. You may want to exclude GPU 0 which
    has less than 75% of the memory or cores of GPU 8. You can do so by setting
    the device_ids argument to DataParallel, or by setting the CUDA_VISIBLE_DEVICES
    environment variable.
  warnings.warn(imbalance_warn.format(device_ids[min_pos], device_ids[max_pos]))
eval_it_pool:  [1000]

================== Exp 0 ==================
 
Hyper-parameters: 
 {'method': 'DC', 'dataset': 'MNIST', 'model': 'ConvNet', 'ipc': 10, 'eval_mode': 'MLP', 'num_exp': 5, 'num_eval': 20, 'epoch_eval_train': 300, 'Iteration': 1000, 'lr_img': 0.1, 'lr_net': 0.01, 'batch_real': 256, 'batch_train': 256, 'init': 'noise', 'dsa_strategy': 'None', 'data_path': 'data', 'save_path': 'result', 'dis_metric': 'ours', 'outer_loop': 10, 'inner_loop': 50, 'device': 'cuda', 'dsa_param': <utils.ParamDiffAug object at 0x7fade2e65ad0>, 'dsa': False}
Evaluation model pool:  ['ConvNet']
class c = 0: 5923 real images
class c = 1: 6742 real images
class c = 2: 5958 real images
class c = 3: 6131 real images
class c = 4: 5842 real images
class c = 5: 5421 real images
class c = 6: 5918 real images
class c = 7: 6265 real images
class c = 8: 5851 real images
class c = 9: 5949 real images
real images channel 0, mean = -0.0001, std = 1.0000
initialize synthetic data from random noise
[2022-05-28 18:15:41] training begins
Traceback (most recent call last):
  File "main.py", line 236, in <module>
    main()
  File "main.py", line 190, in main
    output_real = net(img_real)
  File "/home/zfgao/anaconda3/envs/dc/lib/python3.7/site-packages/torch/nn/modules/module.py", line 547, in __call__
    result = self.forward(*input, **kwargs)
  File "/home/zfgao/anaconda3/envs/dc/lib/python3.7/site-packages/torch/nn/parallel/data_parallel.py", line 152, in forward
    outputs = self.parallel_apply(replicas, inputs, kwargs)
  File "/home/zfgao/anaconda3/envs/dc/lib/python3.7/site-packages/torch/nn/parallel/data_parallel.py", line 162, in parallel_apply
    return parallel_apply(replicas, inputs, kwargs, self.device_ids[:len(replicas)])
  File "/home/zfgao/anaconda3/envs/dc/lib/python3.7/site-packages/torch/nn/parallel/parallel_apply.py", line 85, in parallel_apply
    output.reraise()
  File "/home/zfgao/anaconda3/envs/dc/lib/python3.7/site-packages/torch/_utils.py", line 369, in reraise
    raise self.exc_type(msg)
RuntimeError: Caught RuntimeError in replica 0 on device 0.
Original Traceback (most recent call last):
  File "/home/zfgao/anaconda3/envs/dc/lib/python3.7/site-packages/torch/nn/parallel/parallel_apply.py", line 60, in _worker
    output = module(*input, **kwargs)
  File "/home/zfgao/anaconda3/envs/dc/lib/python3.7/site-packages/torch/nn/modules/module.py", line 547, in __call__
    result = self.forward(*input, **kwargs)
  File "/home/zfgao/work/DatasetCondensation/networks.py", line 45, in forward
    out = self.features(x)
  File "/home/zfgao/anaconda3/envs/dc/lib/python3.7/site-packages/torch/nn/modules/module.py", line 547, in __call__
    result = self.forward(*input, **kwargs)
  File "/home/zfgao/anaconda3/envs/dc/lib/python3.7/site-packages/torch/nn/modules/container.py", line 92, in forward
    input = module(input)
  File "/home/zfgao/anaconda3/envs/dc/lib/python3.7/site-packages/torch/nn/modules/module.py", line 547, in __call__
    result = self.forward(*input, **kwargs)
  File "/home/zfgao/anaconda3/envs/dc/lib/python3.7/site-packages/torch/nn/modules/conv.py", line 343, in forward
    return self.conv2d_forward(input, self.weight)
  File "/home/zfgao/anaconda3/envs/dc/lib/python3.7/site-packages/torch/nn/modules/conv.py", line 340, in conv2d_forward
    self.padding, self.dilation, self.groups)
RuntimeError: cuDNN error: CUDNN_STATUS_EXECUTION_FAILED

